Workbook

Sheet Assumptions
A1: Lab Cost Generator - Assumptions & AWS Rate Card
A3: Global Inputs (edit yellow cells)
A4: Hours per Training Day | B4: 8 | C4: hours
A5: Number of Participants | B5: 60 | C5: learners
A6: USD to INR Conversion Rate | B6: 83 | C6: INR per USD 1
A7: Cloud Provider | B7: AWS | C7: AWS / Azure / GCP
A10: AWS Rate Card (approximate on-demand US pricing; verify region and current rates before final budget)
A11: Key | B11: Tool / Cloud Resource | C11: Billing Unit | D11: Rate (USD) | E11: Use Case | F11: Source / Note
A12: compute_light | B12: EC2 t3.medium | C12: per_hour | D12: 0.0416 | E12: General labs: Python, Linux, Git, scripting | F12: User-provided Multi-Cloud Tool Cost Dataset (Aug 2026 approximate rate)
A13: compute_heavy | B13: EC2 t3.xlarge | C13: per_hour | D13: 0.167 | E13: Docker, Kubernetes, Jenkins, CI/CD, capstones | F13: User-provided Multi-Cloud Tool Cost Dataset (Aug 2026 approximate rate)
A14: managed_kubernetes | B14: EKS control plane | C14: per_hour_per_cluster | D14: 0.1 | E14: Managed cluster control plane | F14: User-provided Multi-Cloud Tool Cost Dataset (Aug 2026 approximate rate)
A15: block_storage | B15: EBS gp3 | C15: per_gb_month | D15: 0.08 | E15: SSD disk attached to a virtual machine | F15: User-provided Multi-Cloud Tool Cost Dataset (Aug 2026 approximate rate)
A16: object_storage | B16: S3 Standard | C16: per_gb_month | D16: 0.023 | E16: Hot or standard object storage | F16: User-provided Multi-Cloud Tool Cost Dataset (Aug 2026 approximate rate)
A17: load_balancer | B17: Application Load Balancer | C17: per_hour_plus_data | D17: 0.025 | E17: HTTP(S) or TCP load balancing | F17: User-provided Multi-Cloud Tool Cost Dataset (Aug 2026 approximate rate)
A18: nat_gateway | B18: NAT Gateway | C18: per_hour_plus_data | D18: 0.045 | E18: Outbound internet for private subnets | F18: User-provided Multi-Cloud Tool Cost Dataset (Aug 2026 approximate rate)
A19: data_egress | B19: Data Transfer Out | C19: per_gb | D19: 0.09 | E19: Outbound internet data transfer | F19: User-provided Multi-Cloud Tool Cost Dataset (Aug 2026 approximate rate)
A20: build_runner | B20: CodeBuild general1.small | C20: per_build_minute | D20: 0.005 | E20: Managed build-minute billing | F20: User-provided Multi-Cloud Tool Cost Dataset (Aug 2026 approximate rate)
A21: container_registry | B21: ECR | C21: per_gb_month | D21: 0.1 | E21: Private container image storage | F21: User-provided Multi-Cloud Tool Cost Dataset (Aug 2026 approximate rate)
A22: relational_db | B22: RDS db.t3.medium | C22: per_hour | D22: 0.068 | E22: Small development or test database | F22: User-provided Multi-Cloud Tool Cost Dataset (Aug 2026 approximate rate)
A23: monitoring | B23: CloudWatch Logs | C23: per_gb_ingested | D23: 0.5 | E23: Log ingestion beyond the free tier | F23: User-provided Multi-Cloud Tool Cost Dataset (Aug 2026 approximate rate)
A25: Free / Third-Party Tool Rules
A26: Tool Group | B26: Billing Type | C26: Rate (USD) | D26: Notes
A27: Docker / Kubernetes self-managed / Git / Jenkins / SonarQube / Maven / Ansible / Terraform / Helm | B27: free | C27: 0 | D27: Open-source; underlying cloud compute may still be billed
A28: Jira / Datadog / Claude / Factory.AI / Harness.io / OpenAI / LangChain / LangGraph / Langfuse | B28: third_party | C28: 0 | D28: Not cloud-provider billed; vendor charges are tracked separately

Sheet Lab Cost
A1: AWS Lab Cost by TOC Line Item - DevOps Mastery
A2: Parent TOC rows carry costs. Indented session topics show tool usage only and are already covered by the parent day.
A4: S# | B4: Category | C4: Topic (as per TOC) | D4: Day(s) | E4: Tool / Cloud Resource Required | F4: Billing Type | G4: Rate/Hr (USD) | H4: Rate/Hr (INR) | I4: N-Hr Day Cost (INR) | J4: Total Hrs for Topic | K4: No. of Participants | L4: Cost/Participant (INR) | M4: TOTAL Cost (INR)
A5: 1 | B5: Core Learning | C5: DevOps Orientation, SDLC and Agile Delivery | D5: Day 1 | E5: EC2 t3.xlarge | F5: AWS EC2 (billed hourly, N-hr lab day) | G5: ='Assumptions'!$D$13 | H5: =G5*'Assumptions'!$B$6 | I5: =G5*'Assumptions'!$B$4*'Assumptions'!$B$6 | J5: =1*'Assumptions'!$B$4 | K5: ='Assumptions'!$B$5 | L5: =G5*J5*'Assumptions'!$B$6 | M5: =L5*K5
C6: > DevOps lifecycle, Agile vs DevOps, CI/CD overview | D6: - | E6: EC2 t3.xlarge | F6: AWS EC2 (billed hourly, N-hr lab day) | G6: ='Assumptions'!$D$13 | H6: =G6*'Assumptions'!$B$6 | I6: - | J6: - | K6: - | L6: - | M6: -
C7: > Break | D7: - | E7: EC2 t3.medium | F7: AWS EC2 (billed hourly, N-hr lab day) | G7: ='Assumptions'!$D$12 | H7: =G7*'Assumptions'!$B$6 | I7: - | J7: - | K7: - | L7: - | M7: -
C8: > Jira workflow, delivery roles | D8: - | E8: Jira | F8: Free / 3rd-party (not cloud-provider billed) | G8: =0 | H8: =G8*'Assumptions'!$B$6 | I8: - | J8: - | K8: - | L8: - | M8: -
C9: > Knowledge check, use cases, and Q&A for DevOps Orientation, SDLC and Agile Delivery | D9: - | E9: EC2 t3.medium | F9: AWS EC2 (billed hourly, N-hr lab day) | G9: ='Assumptions'!$D$12 | H9: =G9*'Assumptions'!$B$6 | I9: - | J9: - | K9: - | L9: - | M9: -
C10: > DevOps Orientation, SDLC and Agile Delivery hands-on implementation, DevOps Orientation, SDLC and Agile Delivery troubleshooting scenarios, DevOps Orientation, SDLC and Agile Delivery best practices and review | D10: - | E10: EC2 t3.medium | F10: AWS EC2 (billed hourly, N-hr lab day) | G10: ='Assumptions'!$D$12 | H10: =G10*'Assumptions'!$B$6 | I10: - | J10: - | K10: - | L10: - | M10: -
C11: > Lab: Create a Jira sprint board and map a sample application delivery workflow | D11: - | E11: Jira | F11: Free / 3rd-party (not cloud-provider billed) | G11: =0 | H11: =G11*'Assumptions'!$B$6 | I11: - | J11: - | K11: - | L11: - | M11: -
C12: > Jira: Create epics, stories, tasks and move them on sprint board | D12: - | E12: Jira | F12: Free / 3rd-party (not cloud-provider billed) | G12: =0 | H12: =G12*'Assumptions'!$B$6 | I12: - | J12: - | K12: - | L12: - | M12: -
A13: 2 | B13: Core Learning | C13: Networking, SSH and Web Basics | D13: Day 2 | E13: Jira | F13: Free / 3rd-party (not cloud-provider billed) | G13: =0 | H13: =G13*'Assumptions'!$B$6 | I13: =G13*'Assumptions'!$B$4*'Assumptions'!$B$6 | J13: =1*'Assumptions'!$B$4 | K13: ='Assumptions'!$B$5 | L13: =G13*J13*'Assumptions'!$B$6 | M13: =L13*K13
C14: > TCP/IP, DNS, HTTP/HTTPS | D14: - | E14: EC2 t3.medium | F14: Free / 3rd-party (not cloud-provider billed) | G14: ='Assumptions'!$D$12 | H14: =G14*'Assumptions'!$B$6 | I14: - | J14: - | K14: - | L14: - | M14: -
C15: > Break | D15: - | E15: EC2 t3.medium | F15: Free / 3rd-party (not cloud-provider billed) | G15: ='Assumptions'!$D$12 | H15: =G15*'Assumptions'!$B$6 | I15: - | J15: - | K15: - | L15: - | M15: -
C16: > ports, SSH | D16: - | E16: EC2 t3.medium | F16: Free / 3rd-party (not cloud-provider billed) | G16: ='Assumptions'!$D$12 | H16: =G16*'Assumptions'!$B$6 | I16: - | J16: - | K16: - | L16: - | M16: -
C17: > Knowledge check, use cases, and Q&A for Networking, SSH and Web Basics | D17: - | E17: EC2 t3.medium | F17: Free / 3rd-party (not cloud-provider billed) | G17: ='Assumptions'!$D$12 | H17: =G17*'Assumptions'!$B$6 | I17: - | J17: - | K17: - | L17: - | M17: -
C18: > curl troubleshooting, Networking, SSH and Web Basics hands-on implementation, Networking, SSH and Web Basics troubleshooting scenarios | D18: - | E18: EC2 t3.medium | F18: Free / 3rd-party (not cloud-provider billed) | G18: ='Assumptions'!$D$12 | H18: =G18*'Assumptions'!$B$6 | I18: - | J18: - | K18: - | L18: - | M18: -
C19: > Lab: Troubleshoot service connectivity using curl, ports and SSH | D19: - | E19: EC2 t3.medium | F19: Free / 3rd-party (not cloud-provider billed) | G19: ='Assumptions'!$D$12 | H19: =G19*'Assumptions'!$B$6 | I19: - | J19: - | K19: - | L19: - | M19: -
C20: > Jira: Create troubleshooting sub-tasks for network incidents | D20: - | E20: Jira | F20: Free / 3rd-party (not cloud-provider billed) | G20: =0 | H20: =G20*'Assumptions'!$B$6 | I20: - | J20: - | K20: - | L20: - | M20: -
A21: 3 | B21: Core Learning | C21: Jenkins Fundamentals | D21: Day 3 | E21: EC2 t3.xlarge | F21: AWS EC2 (billed hourly, N-hr lab day) | G21: ='Assumptions'!$D$13 | H21: =G21*'Assumptions'!$B$6 | I21: =G21*'Assumptions'!$B$4*'Assumptions'!$B$6 | J21: =1*'Assumptions'!$B$4 | K21: ='Assumptions'!$B$5 | L21: =G21*J21*'Assumptions'!$B$6 | M21: =L21*K21
C22: > installation, jobs, agents | D22: - | E22: EC2 t3.medium | F22: AWS EC2 (billed hourly, N-hr lab day) | G22: ='Assumptions'!$D$12 | H22: =G22*'Assumptions'!$B$6 | I22: - | J22: - | K22: - | L22: - | M22: -
C23: > Break | D23: - | E23: EC2 t3.medium | F23: AWS EC2 (billed hourly, N-hr lab day) | G23: ='Assumptions'!$D$12 | H23: =G23*'Assumptions'!$B$6 | I23: - | J23: - | K23: - | L23: - | M23: -
C24: > credentials, plugins | D24: - | E24: EC2 t3.medium | F24: AWS EC2 (billed hourly, N-hr lab day) | G24: ='Assumptions'!$D$12 | H24: =G24*'Assumptions'!$B$6 | I24: - | J24: - | K24: - | L24: - | M24: -
C25: > Knowledge check, use cases, and Q&A for Jenkins Fundamentals | D25: - | E25: EC2 t3.xlarge | F25: AWS EC2 (billed hourly, N-hr lab day) | G25: ='Assumptions'!$D$13 | H25: =G25*'Assumptions'!$B$6 | I25: - | J25: - | K25: - | L25: - | M25: -
C26: > build triggers, Jenkins Fundamentals hands-on implementation, Jenkins Fundamentals troubleshooting scenarios | D26: - | E26: EC2 t3.xlarge | F26: AWS EC2 (billed hourly, N-hr lab day) | G26: ='Assumptions'!$D$13 | H26: =G26*'Assumptions'!$B$6 | I26: - | J26: - | K26: - | L26: - | M26: -
C27: > Lab: Create Jenkins freestyle and pipeline jobs from Git repository | D27: - | E27: EC2 t3.xlarge | F27: AWS EC2 (billed hourly, N-hr lab day) | G27: ='Assumptions'!$D$13 | H27: =G27*'Assumptions'!$B$6 | I27: - | J27: - | K27: - | L27: - | M27: -
C28: > Jira: Create CI task and record Jenkins build URL | D28: - | E28: EC2 t3.xlarge | F28: AWS EC2 (billed hourly, N-hr lab day) | G28: ='Assumptions'!$D$13 | H28: =G28*'Assumptions'!$B$6 | I28: - | J28: - | K28: - | L28: - | M28: -
A29: 4 | B29: Core Learning | C29: Docker Compose and Multi-Container Apps | D29: Day 4 | E29: EC2 t3.xlarge | F29: AWS EC2 (billed hourly, N-hr lab day) | G29: ='Assumptions'!$D$13 | H29: =G29*'Assumptions'!$B$6 | I29: =G29*'Assumptions'!$B$4*'Assumptions'!$B$6 | J29: =1*'Assumptions'!$B$4 | K29: ='Assumptions'!$B$5 | L29: =G29*J29*'Assumptions'!$B$6 | M29: =L29*K29
C30: > compose services, networks, volumes | D30: - | E30: EC2 t3.medium | F30: AWS EC2 (billed hourly, N-hr lab day) | G30: ='Assumptions'!$D$12 | H30: =G30*'Assumptions'!$B$6 | I30: - | J30: - | K30: - | L30: - | M30: -
C31: > Break | D31: - | E31: EC2 t3.medium | F31: AWS EC2 (billed hourly, N-hr lab day) | G31: ='Assumptions'!$D$12 | H31: =G31*'Assumptions'!$B$6 | I31: - | J31: - | K31: - | L31: - | M31: -
C32: > environment variables, health checks | D32: - | E32: EC2 t3.medium | F32: AWS EC2 (billed hourly, N-hr lab day) | G32: ='Assumptions'!$D$12 | H32: =G32*'Assumptions'!$B$6 | I32: - | J32: - | K32: - | L32: - | M32: -
C33: > Knowledge check, use cases, and Q&A for Docker Compose and Multi-Container Apps | D33: - | E33: EC2 t3.xlarge | F33: AWS EC2 (billed hourly, N-hr lab day) | G33: ='Assumptions'!$D$13 | H33: =G33*'Assumptions'!$B$6 | I33: - | J33: - | K33: - | L33: - | M33: -
C34: > Docker Compose and Multi-Container Apps hands-on implementation, Docker Compose and Multi-Container Apps troubleshooting scenarios, Docker Compose and Multi-Container Apps best practices and review | D34: - | E34: EC2 t3.xlarge | F34: AWS EC2 (billed hourly, N-hr lab day) | G34: ='Assumptions'!$D$13 | H34: =G34*'Assumptions'!$B$6 | I34: - | J34: - | K34: - | L34: - | M34: -
C35: > Lab: Run app, database and cache using Docker Compose | D35: - | E35: EC2 t3.xlarge | F35: AWS EC2 (billed hourly, N-hr lab day) | G35: ='Assumptions'!$D$13 | H35: =G35*'Assumptions'!$B$6 | I35: - | J35: - | K35: - | L35: - | M35: -
C36: > Jira: Track compose setup issues and resolution comments | D36: - | E36: Jira | F36: Free / 3rd-party (not cloud-provider billed) | G36: =0 | H36: =G36*'Assumptions'!$B$6 | I36: - | J36: - | K36: - | L36: - | M36: -
A37: 5 | B37: Core Learning | C37: Kubernetes Workloads and Services | D37: Day 5 | E37: EC2 t3.xlarge | F37: AWS EC2 (billed hourly, N-hr lab day) | G37: ='Assumptions'!$D$13 | H37: =G37*'Assumptions'!$B$6 | I37: =G37*'Assumptions'!$B$4*'Assumptions'!$B$6 | J37: =1*'Assumptions'!$B$4 | K37: ='Assumptions'!$B$5 | L37: =G37*J37*'Assumptions'!$B$6 | M37: =L37*K37
C38: > deployments, services, ingress | D38: - | E38: EC2 t3.medium | F38: AWS EC2 (billed hourly, N-hr lab day) | G38: ='Assumptions'!$D$12 | H38: =G38*'Assumptions'!$B$6 | I38: - | J38: - | K38: - | L38: - | M38: -
C39: > Break | D39: - | E39: EC2 t3.medium | F39: AWS EC2 (billed hourly, N-hr lab day) | G39: ='Assumptions'!$D$12 | H39: =G39*'Assumptions'!$B$6 | I39: - | J39: - | K39: - | L39: - | M39: -
C40: > configmaps, secrets | D40: - | E40: EC2 t3.medium | F40: AWS EC2 (billed hourly, N-hr lab day) | G40: ='Assumptions'!$D$12 | H40: =G40*'Assumptions'!$B$6 | I40: - | J40: - | K40: - | L40: - | M40: -
C41: > Knowledge check, use cases, and Q&A for Kubernetes Workloads and Services | D41: - | E41: EC2 t3.xlarge | F41: AWS EC2 (billed hourly, N-hr lab day) | G41: ='Assumptions'!$D$13 | H41: =G41*'Assumptions'!$B$6 | I41: - | J41: - | K41: - | L41: - | M41: -
...
